<?xml version='1.0' encoding='utf-8'?>
<robot name="dual_nero_linker_l10_combined">
  <!--Generated by tools/build_add_scene_combined_urdf.py from add_scene_glb.py assembly constants.-->
  <link name="combined_root" />
  <link name="base_stl">
    <inertial>
      <origin xyz="0 0 0" rpy="0 0 0" />
      <mass value="1.0" />
      <inertia ixx="1e-3" ixy="0" ixz="0" iyy="1e-3" iyz="0" izz="1e-3" />
    </inertial>
    <visual>
      <origin xyz="0 0 0" rpy="0 0 0" />
      <geometry>
        <mesh filename="../nero_twin/assets/mesh/base.STL" scale="0.001 0.001 0.001" />
      </geometry>
    </visual>
  </link>
  <joint name="combined_root_to_base_stl" type="fixed">
    <origin xyz="0.25 -0.25 0" rpy="0 0 0" />
    <parent link="combined_root" />
    <child link="base_stl" />
  </joint>
  <link name="left_world" />
  <joint name="left_world_to_base_link" type="fixed">
    <parent link="left_world" />
    <child link="left_base_link" />
    <origin xyz="0 0 0" rpy="0 0 0" />
  </joint>
  <link name="left_base_link">
    <inertial>
      <origin xyz="-0.00319465997 -0.00005467608 0.04321758463" rpy="0 0 0" />
      <mass value="1.06458435" />
      <inertia ixx="0.00102659855152" ixy="0.00000186219753" ixz="-0.00000295298037" iyy="0.00114399299508" iyz="-0.00000078763492" izz="0.00090872933022" />
    </inertial>
    <visual>
      <origin xyz="0 0 0" rpy="0 0 0" />
      <geometry>
        <mesh filename="../nero_twin/assets/agx_arm_urdf/nero/meshes/dae/base_link.dae" />
      </geometry>
    </visual>
  </link>
  <link name="left_link1">
    <inertial>
      <origin xyz="-0.00076810578 -0.00005718031 -0.00686372765" rpy="0 0 0" />
      <mass value="0.76710504" />
      <inertia ixx="0.00066689512233" ixy="0.00000273938306" ixz="0.00001463284987" iyy="0.00054501235592" iyz="0.00000183168344" izz="0.00051509465737" />
    </inertial>
    <visual>
      <origin xyz="0 0 0" rpy="0 0 0" />
      <geometry>
        <mesh filename="../nero_twin/assets/agx_arm_urdf/nero/meshes/dae/link1.dae" />
      </geometry>
    </visual>
  </link>
  <joint name="left_joint1" type="revolute">
    <origin xyz="0 0 0.138" rpy="0 0 0" />
    <parent link="left_base_link" />
    <child link="left_link1" />
    <axis xyz="0 0 1" />
    <limit lower="-2.70526" upper="2.70526" effort="100" velocity="5" />
  </joint>
  <link name="left_link2">
    <inertial>
      <origin xyz="0.00079686657 -0.07890325930 0.00111849422" rpy="0 0 0" />
      <mass value="0.69381908" />
      <inertia ixx="0.00201093857656" ixy="-0.00002399426785" ixz="-0.00000072824714" iyy="0.00063544232555" iyz="0.00005831284343" izz="0.00181943989593" />
    </inertial>
    <visual>
      <origin xyz="0 0 0" rpy="0 0 0" />
      <geometry>
        <mesh filename="../nero_twin/assets/agx_arm_urdf/nero/meshes/dae/link2.dae" />
      </geometry>
    </visual>
  </link>
  <joint name="left_joint2" type="revolute">
    <origin xyz="0 0 0" rpy="1.5707963  3.1415926 0" />
    <parent link="left_link1" />
    <child link="left_link2" />
    <axis xyz="0 0 1" />
    <limit lower="-1.74" upper="1.74" effort="100" velocity="5" />
  </joint>
  <link name="left_link3">
    <inertial>
      <origin xyz="0.00014513363 -0.00121378766 -0.04861136795" rpy="0 0 0" />
      <mass value="0.67246544" />
      <inertia ixx="0.00343229961910" ixy="-0.00000026976739" ixz="0.00000305078107" iyy="0.00338662526897" iyz="-0.00003550220027" izz="0.00028853579710" />
    </inertial>
    <visual>
      <origin xyz="0 0 0" rpy="0 0 0" />
      <geometry>
        <mesh filename="../nero_twin/assets/agx_arm_urdf/nero/meshes/dae/link3.dae" />
      </geometry>
    </visual>
  </link>
  <joint name="left_joint3" type="revolute">
    <origin xyz="0 -0.31 0" rpy="-1.5707963  0 3.1415926926" />
    <parent link="left_link2" />
    <child link="left_link3" />
    <axis xyz="0 0 1" />
    <limit lower="-2.75" upper="2.75" effort="100" velocity="5" />
  </joint>
  <link name="left_link4">
    <inertial>
      <origin xyz="-0.00031334623 -0.05675192422 0.00076056133" rpy="0 0 0" />
      <mass value="0.48451414" />
      <inertia ixx="0.00050386693505" ixy="-0.00000529675237" ixz="0.00000006134740" iyy="0.00023502068202" iyz="0.00001815932566" izz="0.00040149523118" />
    </inertial>
    <visual>
      <origin xyz="0 0 0" rpy="0 0 0" />
      <geometry>
        <mesh filename="../nero_twin/assets/agx_arm_urdf/nero/meshes/dae/link4.dae" />
      </geometry>
    </visual>
  </link>
  <joint name="left_joint4" type="revolute">
    <origin xyz="0 0 0" rpy="-1.5707963  0 3.1415926926" />
    <parent link="left_link3" />
    <child link="left_link4" />
    <axis xyz="0 0 1" />
    <limit lower="-1.01" upper="2.14" effort="100" velocity="5" />
  </joint>
  <link name="left_link5">
    <inertial>
      <origin xyz="0.00265591357 0.00201195753 -0.11620855434" rpy="0 0 0" />
      <mass value="0.58368405" />
      <inertia ixx="0.00089537686723" ixy="0.00000648218232" ixz="-0.00001463346849" iyy="0.00085866122972" iyz="-0.00004035185637" izz="0.00021774946532" />
    </inertial>
    <visual>
      <origin xyz="0 0 0" rpy="0 0 0" />
      <geometry>
        <mesh filename="../nero_twin/assets/agx_arm_urdf/nero/meshes/dae/link5.dae" />
      </geometry>
    </visual>
  </link>
  <joint name="left_joint5" type="revolute">
    <origin xyz="0 -0.27001 0" rpy="1.5707963  -1.5707963  0" />
    <parent link="left_link4" />
    <child link="left_link5" />
    <axis xyz="0 0 1" />
    <limit lower="-2.75" upper="2.75" effort="100" velocity="5" />
  </joint>
  <link name="left_link6">
    <inertial>
      <origin xyz="0.00009501505 0.00107831174 -0.00019110990" rpy="0 0 0" />
      <mass value="0.3140406" />
      <inertia ixx="0.00006027211661" ixy="-0.00000024650903" ixz="0.00000015701294" iyy="0.00004699514792" iyz="0.00000004170875" izz="0.00005756771792" />
    </inertial>
    <visual>
      <origin xyz="0 0 0" rpy="0 0 0" />
      <geometry>
        <mesh filename="../nero_twin/assets/agx_arm_urdf/nero/meshes/dae/link6.dae" />
      </geometry>
    </visual>
  </link>
  <joint name="left_joint6" type="revolute">
    <origin xyz="0 0 0" rpy="1.5707963  -1.5707963  0" />
    <parent link="left_link5" />
    <child link="left_link6" />
    <axis xyz="0 0 1" />
    <limit lower="-0.73" upper="0.95" effort="100" velocity="5" />
  </joint>
  <link name="left_link7">
    <inertial>
      <origin xyz="-0.00014000 -0.00010000 -0.00275000" rpy="0 0 0" />
      <mass value="0.000001" />
      <inertia ixx="1.1000000000000001e-07" ixy="0" ixz="0" iyy="1.1000000000000001e-07" iyz="0" izz="1.9999999999999999e-07" />
    </inertial>
    <visual>
      <origin xyz="0 0 0" rpy="0 0 0" />
      <geometry>
        <mesh filename="../nero_twin/assets/agx_arm_urdf/nero/meshes/dae/link7.dae" />
      </geometry>
    </visual>
  </link>
  <joint name="left_joint7" type="revolute">
    <origin xyz="0 -0.0235 0" rpy="1.5707963 0 0" />
    <parent link="left_link6" />
    <child link="left_link7" />
    <axis xyz="0 0 1" />
    <limit lower="-1.5707963" upper="1.5707963" effort="100" velocity="5" />
  </joint>
  <link name="left_revo2_flange">
    <inertial>
      <origin xyz="0.0 0.0 -0.00032" rpy="0 0 0" />
      <mass value="0.04771096" />
      <inertia ixx="2.697e-05" ixy="0" ixz="0" iyy="4.311e-05" iyz="0" izz="2.479e-05" />
    </inertial>
    <visual>
      <origin xyz="0 0 0" rpy="0 0 0" />
      <geometry>
        <mesh filename="../nero_twin/assets/agx_arm_urdf/nero/meshes/dae/revo2_flange.dae" />
      </geometry>
    </visual>
  </link>
  <joint name="left_revo2_flange_joint" type="fixed">
    <origin xyz="0.032 0 -0.0235" rpy="-1.5708 0 -1.5708" />
    <parent link="left_link7" />
    <child link="left_revo2_flange" />
  </joint>
  <link name="right_world" />
  <joint name="right_world_to_base_link" type="fixed">
    <parent link="right_world" />
    <child link="right_base_link" />
    <origin xyz="0 0 0" rpy="0 0 0" />
  </joint>
  <link name="right_base_link">
    <inertial>
      <origin xyz="-0.00319465997 -0.00005467608 0.04321758463" rpy="0 0 0" />
      <mass value="1.06458435" />
      <inertia ixx="0.00102659855152" ixy="0.00000186219753" ixz="-0.00000295298037" iyy="0.00114399299508" iyz="-0.00000078763492" izz="0.00090872933022" />
    </inertial>
    <visual>
      <origin xyz="0 0 0" rpy="0 0 0" />
      <geometry>
        <mesh filename="../nero_twin/assets/agx_arm_urdf/nero/meshes/dae/base_link.dae" />
      </geometry>
    </visual>
  </link>
  <link name="right_link1">
    <inertial>
      <origin xyz="-0.00076810578 -0.00005718031 -0.00686372765" rpy="0 0 0" />
      <mass value="0.76710504" />
      <inertia ixx="0.00066689512233" ixy="0.00000273938306" ixz="0.00001463284987" iyy="0.00054501235592" iyz="0.00000183168344" izz="0.00051509465737" />
    </inertial>
    <visual>
      <origin xyz="0 0 0" rpy="0 0 0" />
      <geometry>
        <mesh filename="../nero_twin/assets/agx_arm_urdf/nero/meshes/dae/link1.dae" />
      </geometry>
    </visual>
  </link>
  <joint name="right_joint1" type="revolute">
    <origin xyz="0 0 0.138" rpy="0 0 0" />
    <parent link="right_base_link" />
    <child link="right_link1" />
    <axis xyz="0 0 1" />
    <limit lower="-2.70526" upper="2.70526" effort="100" velocity="5" />
  </joint>
  <link name="right_link2">
    <inertial>
      <origin xyz="0.00079686657 -0.07890325930 0.00111849422" rpy="0 0 0" />
      <mass value="0.69381908" />
      <inertia ixx="0.00201093857656" ixy="-0.00002399426785" ixz="-0.00000072824714" iyy="0.00063544232555" iyz="0.00005831284343" izz="0.00181943989593" />
    </inertial>
    <visual>
      <origin xyz="0 0 0" rpy="0 0 0" />
      <geometry>
        <mesh filename="../nero_twin/assets/agx_arm_urdf/nero/meshes/dae/link2.dae" />
      </geometry>
    </visual>
  </link>
  <joint name="right_joint2" type="revolute">
    <origin xyz="0 0 0" rpy="1.5707963  3.1415926 0" />
    <parent link="right_link1" />
    <child link="right_link2" />
    <axis xyz="0 0 1" />
    <limit lower="-1.74" upper="1.74" effort="100" velocity="5" />
  </joint>
  <link name="right_link3">
    <inertial>
      <origin xyz="0.00014513363 -0.00121378766 -0.04861136795" rpy="0 0 0" />
      <mass value="0.67246544" />
      <inertia ixx="0.00343229961910" ixy="-0.00000026976739" ixz="0.00000305078107" iyy="0.00338662526897" iyz="-0.00003550220027" izz="0.00028853579710" />
    </inertial>
    <visual>
      <origin xyz="0 0 0" rpy="0 0 0" />
      <geometry>
        <mesh filename="../nero_twin/assets/agx_arm_urdf/nero/meshes/dae/link3.dae" />
      </geometry>
    </visual>
  </link>
  <joint name="right_joint3" type="revolute">
    <origin xyz="0 -0.31 0" rpy="-1.5707963  0 3.1415926926" />
    <parent link="right_link2" />
    <child link="right_link3" />
    <axis xyz="0 0 1" />
    <limit lower="-2.75" upper="2.75" effort="100" velocity="5" />
  </joint>
  <link name="right_link4">
    <inertial>
      <origin xyz="-0.00031334623 -0.05675192422 0.00076056133" rpy="0 0 0" />
      <mass value="0.48451414" />
      <inertia ixx="0.00050386693505" ixy="-0.00000529675237" ixz="0.00000006134740" iyy="0.00023502068202" iyz="0.00001815932566" izz="0.00040149523118" />
    </inertial>
    <visual>
      <origin xyz="0 0 0" rpy="0 0 0" />
      <geometry>
        <mesh filename="../nero_twin/assets/agx_arm_urdf/nero/meshes/dae/link4.dae" />
      </geometry>
    </visual>
  </link>
  <joint name="right_joint4" type="revolute">
    <origin xyz="0 0 0" rpy="-1.5707963  0 3.1415926926" />
    <parent link="right_link3" />
    <child link="right_link4" />
    <axis xyz="0 0 1" />
    <limit lower="-1.01" upper="2.14" effort="100" velocity="5" />
  </joint>
  <link name="right_link5">
    <inertial>
      <origin xyz="0.00265591357 0.00201195753 -0.11620855434" rpy="0 0 0" />
      <mass value="0.58368405" />
      <inertia ixx="0.00089537686723" ixy="0.00000648218232" ixz="-0.00001463346849" iyy="0.00085866122972" iyz="-0.00004035185637" izz="0.00021774946532" />
    </inertial>
    <visual>
      <origin xyz="0 0 0" rpy="0 0 0" />
      <geometry>
        <mesh filename="../nero_twin/assets/agx_arm_urdf/nero/meshes/dae/link5.dae" />
      </geometry>
    </visual>
  </link>
  <joint name="right_joint5" type="revolute">
    <origin xyz="0 -0.27001 0" rpy="1.5707963  -1.5707963  0" />
    <parent link="right_link4" />
    <child link="right_link5" />
    <axis xyz="0 0 1" />
    <limit lower="-2.75" upper="2.75" effort="100" velocity="5" />
  </joint>
  <link name="right_link6">
    <inertial>
      <origin xyz="0.00009501505 0.00107831174 -0.00019110990" rpy="0 0 0" />
      <mass value="0.3140406" />
      <inertia ixx="0.00006027211661" ixy="-0.00000024650903" ixz="0.00000015701294" iyy="0.00004699514792" iyz="0.00000004170875" izz="0.00005756771792" />
    </inertial>
    <visual>
      <origin xyz="0 0 0" rpy="0 0 0" />
      <geometry>
        <mesh filename="../nero_twin/assets/agx_arm_urdf/nero/meshes/dae/link6.dae" />
      </geometry>
    </visual>
  </link>
  <joint name="right_joint6" type="revolute">
    <origin xyz="0 0 0" rpy="1.5707963  -1.5707963  0" />
    <parent link="right_link5" />
    <child link="right_link6" />
    <axis xyz="0 0 1" />
    <limit lower="-0.73" upper="0.95" effort="100" velocity="5" />
  </joint>
  <link name="right_link7">
    <inertial>
      <origin xyz="-0.00014000 -0.00010000 -0.00275000" rpy="0 0 0" />
      <mass value="0.000001" />
      <inertia ixx="1.1000000000000001e-07" ixy="0" ixz="0" iyy="1.1000000000000001e-07" iyz="0" izz="1.9999999999999999e-07" />
    </inertial>
    <visual>
      <origin xyz="0 0 0" rpy="0 0 0" />
      <geometry>
        <mesh filename="../nero_twin/assets/agx_arm_urdf/nero/meshes/dae/link7.dae" />
      </geometry>
    </visual>
  </link>
  <joint name="right_joint7" type="revolute">
    <origin xyz="0 -0.0235 0" rpy="1.5707963 0 0" />
    <parent link="right_link6" />
    <child link="right_link7" />
    <axis xyz="0 0 1" />
    <limit lower="-1.5707963" upper="1.5707963" effort="100" velocity="5" />
  </joint>
  <link name="right_revo2_flange">
    <inertial>
      <origin xyz="0.0 0.0 -0.00032" rpy="0 0 0" />
      <mass value="0.04771096" />
      <inertia ixx="2.697e-05" ixy="0" ixz="0" iyy="4.311e-05" iyz="0" izz="2.479e-05" />
    </inertial>
    <visual>
      <origin xyz="0 0 0" rpy="0 0 0" />
      <geometry>
        <mesh filename="../nero_twin/assets/agx_arm_urdf/nero/meshes/dae/revo2_flange.dae" />
      </geometry>
    </visual>
  </link>
  <joint name="right_revo2_flange_joint" type="fixed">
    <origin xyz="0.032 0 -0.0235" rpy="-1.5708 0 -1.5708" />
    <parent link="right_link7" />
    <child link="right_revo2_flange" />
  </joint>
  <joint name="base_stl_to_left_nero" type="fixed">
    <origin xyz="-0.253 0.194 1.078" rpy="1.57079633 -1.57079633 0" />
    <parent link="base_stl" />
    <child link="left_world" />
  </joint>
  <joint name="base_stl_to_right_nero" type="fixed">
    <origin xyz="-0.253 0.312 1.078" rpy="-1.57079633 -1.57079633 0" />
    <parent link="base_stl" />
    <child link="right_world" />
  </joint>
  <link name="left_connector">
    <inertial>
      <origin xyz="0 0 0" rpy="0 0 0" />
      <mass value="1.0" />
      <inertia ixx="1e-3" ixy="0" ixz="0" iyy="1e-3" iyz="0" izz="1e-3" />
    </inertial>
    <visual>
      <origin xyz="0 0 0" rpy="0 0 0" />
      <geometry>
        <mesh filename="../connector.STL" scale="0.001 0.001 0.001" />
      </geometry>
    </visual>
  </link>
  <link name="right_connector">
    <inertial>
      <origin xyz="0 0 0" rpy="0 0 0" />
      <mass value="1.0" />
      <inertia ixx="1e-3" ixy="0" ixz="0" iyy="1e-3" iyz="0" izz="1e-3" />
    </inertial>
    <visual>
      <origin xyz="0 0 0" rpy="0 0 0" />
      <geometry>
        <mesh filename="../connector.STL" scale="0.001 0.001 0.001" />
      </geometry>
    </visual>
  </link>
  <joint name="left_revo2_flange_to_connector" type="fixed">
    <origin xyz="-0.023 -0.089 0.038" rpy="-1.57079633 -0.00523598776 0" />
    <parent link="left_revo2_flange" />
    <child link="left_connector" />
  </joint>
  <joint name="right_revo2_flange_to_connector" type="fixed">
    <origin xyz="0.022 0.089 0.038" rpy="-1.57079633 -0 3.14159265" />
    <parent link="right_revo2_flange" />
    <child link="right_connector" />
  </joint>
  <link name="right_l10_hand_base_link">
    <inertial>
      <origin xyz="-0.00378572993474923 -0.000415839048931058 0.0836392883613671" rpy="0 0 0" />
      <mass value="0.10884427610512" />
      <inertia ixx="0.00019345483956042" ixy="1.28842682703635E-06" ixz="1.97005632028112E-07" iyy="0.000129793182936336" iyz="-2.34961034039841E-06" izz="7.75126657491835E-05" />
    </inertial>
    <visual>
      <origin xyz="0 0 0" rpy="0 0 0" />
      <geometry>
        <mesh filename="../linkerhand-urdf/l10/right/meshes/hand_base_link.STL" />
      </geometry>
      <material name="right_l10_silver_white">
        <color rgba="0.86 0.88 0.88 1" />
      </material>
    </visual>
    <collision>
      <origin xyz="0 0 0" rpy="0 0 0" />
      <geometry>
        <mesh filename="../linkerhand-urdf/l10/right/meshes/hand_base_link.STL" />
      </geometry>
    </collision>
  </link>
  <link name="right_l10_thumb_metacarpals_base1">
    <inertial>
      <origin xyz="0.0284774593036823 -0.00319295610820959 0.000288698025133524" rpy="0 0 0" />
      <mass value="0.0084581719416891" />
      <inertia ixx="1.40261950876138E-06" ixy="1.18207329998214E-07" ixz="-1.77710409325651E-08" iyy="9.82563824235415E-07" iyz="-6.88503841796069E-08" izz="7.36195207923163E-07" />
    </inertial>
    <visual>
      <origin xyz="0 0 0" rpy="0 0 0" />
      <geometry>
        <mesh filename="../linkerhand-urdf/l10/right/meshes/thumb_metacarpals_base1.STL" />
      </geometry>
      <material name="right_l10_silver_white">
        <color rgba="0.86 0.88 0.88 1" />
      </material>
    </visual>
    <collision>
      <origin xyz="0 0 0" rpy="0 0 0" />
      <geometry>
        <mesh filename="../linkerhand-urdf/l10/right/meshes/thumb_metacarpals_base1.STL" />
      </geometry>
    </collision>
  </link>
  <joint name="right_l10_thumb_cmc_roll" type="revolute">
    <origin xyz="-0.013419 0.012551 0.060602" rpy="0 0 0" />
    <parent link="right_l10_hand_base_link" />
    <child link="right_l10_thumb_metacarpals_base1" />
    <axis xyz="0.99996 0 -0.0087265" />
    <limit lower="0" upper="1.1339" effort="100" velocity="1" />
  </joint>
  <link name="right_l10_thumb_metacarpals_base2">
    <inertial>
      <origin xyz="0.00215248483593253 0.00687960824638228 -0.00178648738539141" rpy="0 0 0" />
      <mass value="0.00582710536801184" />
      <inertia ixx="3.1580508435925E-07" ixy="-1.2523312776122E-08" ixz="7.34627751822501E-09" iyy="2.74551538715439E-07" iyz="-1.11420623852877E-08" izz="1.7708647486189E-07" />
    </inertial>
    <visual>
      <origin xyz="0 0 0" rpy="0 0 0" />
      <geometry>
        <mesh filename="../linkerhand-urdf/l10/right/meshes/thumb_metacarpals_base2.STL" />
      </geometry>
      <material name="right_l10_silver_white">
        <color rgba="0.86 0.88 0.88 1" />
      </material>
    </visual>
    <collision>
      <origin xyz="0 0 0" rpy="0 0 0" />
      <geometry>
        <mesh filename="../linkerhand-urdf/l10/right/meshes/thumb_metacarpals_base2.STL" />
      </geometry>
    </collision>
  </link>
  <joint name="right_l10_thumb_cmc_yaw" type="revolute">
    <origin xyz="0.035797 -0.00065879 0.00045944" rpy="0 0 0" />
    <parent link="right_l10_thumb_metacarpals_base1" />
    <child link="right_l10_thumb_metacarpals_base2" />
    <axis xyz="0.008517 -0.21782 -0.97595" />
    <limit lower="0" upper="1.9189" effort="100" velocity="0" />
  </joint>
  <link name="right_l10_thumb_metacarpals">
    <inertial>
      <origin xyz="0.00183661834550107 -2.80742940476572E-06 0.0269905020099197" rpy="0 0 0" />
      <mass value="0.0152011697874328" />
      <inertia ixx="2.95370119498705E-06" ixy="5.98576599418973E-11" ixz="1.58078022444628E-07" iyy="3.84770651487058E-06" iyz="4.18316149481869E-10" izz="1.32007495243356E-06" />
    </inertial>
    <visual>
      <origin xyz="0 0 0" rpy="0 0 0" />
      <geometry>
        <mesh filename="../linkerhand-urdf/l10/right/meshes/thumb_metacarpals.STL" />
      </geometry>
      <material name="right_l10_silver_white">
        <color rgba="0.86 0.88 0.88 1" />
      </material>
    </visual>
    <collision>
      <origin xyz="0 0 0" rpy="0 0 0" />
      <geometry>
        <mesh filename="../linkerhand-urdf/l10/right/meshes/thumb_metacarpals.STL" />
      </geometry>
    </collision>
  </link>
  <joint name="right_l10_thumb_cmc_pitch" type="revolute">
    <origin xyz="0.0046051 0.014383 -0.0051478" rpy="0.16356 -1.1191 -2.0038" />
    <parent link="right_l10_thumb_metacarpals_base2" />
    <child link="right_l10_thumb_metacarpals" />
    <axis xyz="0 1 0" />
    <limit lower="0" upper="0.5146" effort="100" velocity="1" />
  </joint>
  <link name="right_l10_thumb_proximal">
    <inertial>
      <origin xyz="0.00159270226880857 -4.4335770623613E-06 0.0151573535592338" rpy="0 0 0" />
      <mass value="0.00662230120907192" />
      <inertia ixx="1.01526965693255E-06" ixy="-3.40889077339227E-12" ixz="4.4224333375416E-08" iyy="9.10433196570128E-07" iyz="2.59867251981586E-11" izz="4.4746314468008E-07" />
    </inertial>
    <visual>
      <origin xyz="0 0 0" rpy="0 0 0" />
      <geometry>
        <mesh filename="../linkerhand-urdf/l10/right/meshes/thumb_proximal.STL" />
      </geometry>
      <material name="right_l10_silver_white">
        <color rgba="0.86 0.88 0.88 1" />
      </material>
    </visual>
    <collision>
      <origin xyz="0 0 0" rpy="0 0 0" />
      <geometry>
        <mesh filename="../linkerhand-urdf/l10/right/meshes/thumb_proximal.STL" />
      </geometry>
    </collision>
  </link>
  <joint name="right_l10_thumb_mcp" type="revolute">
    <origin xyz="0.0061722 0 0.047968" rpy="0 0 0" />
    <parent link="right_l10_thumb_metacarpals" />
    <child link="right_l10_thumb_proximal" />
    <axis xyz="0 1 0" />
    <limit lower="0" upper="0.7152" effort="100" velocity="1" />
    <mimic joint="right_l10_thumb_cmc_pitch" multiplier="1.3898" offset="0" />
  </joint>
  <link name="right_l10_thumb_distal">
    <inertial>
      <origin xyz="-0.00138919652929166 1.66654390589688E-06 0.0115790399688877" rpy="0 0 0" />
      <mass value="0.00512933613321634" />
      <inertia ixx="3.30969722600772E-07" ixy="-3.44780214263253E-10" ixz="1.04733139974397E-07" iyy="3.23809589950991E-07" iyz="-8.21573772773073E-11" izz="2.489052525811E-07" />
    </inertial>
    <visual>
      <origin xyz="0 0 0" rpy="0 0 0" />
      <geometry>
        <mesh filename="../linkerhand-urdf/l10/right/meshes/thumb_distal.STL" />
      </geometry>
      <material name="right_l10_silver_white">
        <color rgba="0.86 0.88 0.88 1" />
      </material>
    </visual>
    <collision>
      <origin xyz="0 0 0" rpy="0 0 0" />
      <geometry>
        <mesh filename="../linkerhand-urdf/l10/right/meshes/thumb_distal.STL" />
      </geometry>
    </collision>
  </link>
  <joint name="right_l10_thumb_ip" type="revolute">
    <origin xyz="-0.00017064 0 0.038665" rpy="0 0 0" />
    <parent link="right_l10_thumb_proximal" />
    <child link="right_l10_thumb_distal" />
    <axis xyz="0 1 0" />
    <limit lower="0" upper="0.7763" effort="100" velocity="1" />
    <mimic joint="right_l10_thumb_cmc_pitch" multiplier="1.508" offset="0" />
  </joint>
  <link name="right_l10_index_metacarpals">
    <inertial>
      <origin xyz="-0.000473392019250098 -6.96702861594997E-07 0.00909067743061448" rpy="0 0 0" />
      <mass value="0.00903700347459462" />
      <inertia ixx="4.90035722472611E-07" ixy="3.89143802263231E-11" ixz="-2.78580197566548E-08" iyy="7.37380420538667E-07" iyz="6.37050140815271E-11" izz="5.52381285093451E-07" />
    </inertial>
    <visual>
      <origin xyz="0 0 0" rpy="0 0 0" />
      <geometry>
        <mesh filename="../linkerhand-urdf/l10/right/meshes/index_metacarpals.STL" />
      </geometry>
      <material name="right_l10_silver_white">
        <color rgba="0.86 0.88 0.88 1" />
      </material>
    </visual>
    <collision>
      <origin xyz="0 0 0" rpy="0 0 0" />
      <geometry>
        <mesh filename="../linkerhand-urdf/l10/right/meshes/index_metacarpals.STL" />
      </geometry>
    </collision>
  </link>
  <joint name="right_l10_index_mcp_roll" type="revolute">
    <origin xyz="-0.0021643 0.026654 0.13253" rpy="0 0 0" />
    <parent link="right_l10_hand_base_link" />
    <child link="right_l10_index_metacarpals" />
    <axis xyz="-0.99996 0 0.0087265" />
    <limit lower="0" upper="0.2181" effort="100" velocity="1" />
  </joint>
  <link name="right_l10_index_proximal">
    <inertial>
      <origin xyz="-0.000221409784741484 1.17214413283134E-06 0.0104801609243648" rpy="0 0 0" />
      <mass value="0.00654982479821771" />
      <inertia ixx="4.43447817415824E-07" ixy="-2.69774925527114E-12" ixz="2.71645765576885E-08" iyy="4.58697755319572E-07" iyz="-8.52649515921746E-11" izz="1.7465947341041E-07" />
    </inertial>
    <visual>
      <origin xyz="0 0 0" rpy="0 0 0" />
      <geometry>
        <mesh filename="../linkerhand-urdf/l10/right/meshes/index_proximal.STL" />
      </geometry>
      <material name="right_l10_silver_white">
        <color rgba="0.86 0.88 0.88 1" />
      </material>
    </visual>
    <collision>
      <origin xyz="0 0 0" rpy="0 0 0" />
      <geometry>
        <mesh filename="../linkerhand-urdf/l10/right/meshes/index_proximal.STL" />
      </geometry>
    </collision>
  </link>
  <joint name="right_l10_index_mcp_pitch" type="revolute">
    <origin xyz="0.0020763 0 0.015294" rpy="0 0 0" />
    <parent link="right_l10_index_metacarpals" />
    <child link="right_l10_index_proximal" />
    <axis xyz="0 1 0" />
    <limit lower="0" upper="1.3607" effort="100" velocity="1" />
  </joint>
  <link name="right_l10_index_middle">
    <inertial>
      <origin xyz="-0.00259932519148708 -2.09526073980532E-06 0.0110174765184068" rpy="0 0 0" />
      <mass value="0.00283043635595588" />
      <inertia ixx="2.60328472325947E-07" ixy="5.7907596345584E-11" ixz="4.11787064047029E-08" iyy="2.33077669786127E-07" iyz="-2.91977981203693E-11" izz="1.27252395425434E-07" />
    </inertial>
    <visual>
      <origin xyz="0 0 0" rpy="0 0 0" />
      <geometry>
        <mesh filename="../linkerhand-urdf/l10/right/meshes/index_middle.STL" />
      </geometry>
      <material name="right_l10_silver_white">
        <color rgba="0.86 0.88 0.88 1" />
      </material>
    </visual>
    <collision>
      <origin xyz="0 0 0" rpy="0 0 0" />
      <geometry>
        <mesh filename="../linkerhand-urdf/l10/right/meshes/index_middle.STL" />
      </geometry>
    </collision>
  </link>
  <joint name="right_l10_index_pip" type="revolute">
    <origin xyz="-0.0013807 0 0.035624" rpy="0 0 0" />
    <parent link="right_l10_index_proximal" />
    <child link="right_l10_index_middle" />
    <axis xyz="0 1 0" />
    <limit lower="0" upper="1.8317" effort="100" velocity="1" />
    <mimic joint="right_l10_index_mcp_pitch" multiplier="1.3462" offset="0" />
  </joint>
  <link name="right_l10_index_distal">
    <inertial>
      <origin xyz="-0.000710605319534495 5.23484329792434E-06 0.0121456668819466" rpy="0 0 0" />
      <mass value="0.00314458657125681" />
      <inertia ixx="1.63322109883219E-07" ixy="1.96094345230889E-11" ixz="4.33517104700554E-08" iyy="1.48366110942312E-07" iyz="-2.0277830463002E-10" izz="9.85575309385827E-08" />
    </inertial>
    <visual>
      <origin xyz="0 0 0" rpy="0 0 0" />
      <geometry>
        <mesh filename="../linkerhand-urdf/l10/right/meshes/index_distal.STL" />
      </geometry>
      <material name="right_l10_silver_white">
        <color rgba="0.86 0.88 0.88 1" />
      </material>
    </visual>
    <collision>
      <origin xyz="0 0 0" rpy="0 0 0" />
      <geometry>
        <mesh filename="../linkerhand-urdf/l10/right/meshes/index_distal.STL" />
      </geometry>
    </collision>
  </link>
  <joint name="right_l10_index_dip" type="revolute">
    <origin xyz="-0.0054686 0 0.025665" rpy="0 0 0" />
    <parent link="right_l10_index_middle" />
    <child link="right_l10_index_distal" />
    <axis xyz="0 1 0" />
    <limit lower="0" upper="1.8317" effort="100" velocity="1" />
    <mimic joint="right_l10_index_mcp_pitch" multiplier="0.4616" offset="0" />
  </joint>
  <link name="right_l10_middle_proximal">
    <inertial>
      <origin xyz="-0.000226219980586555 1.17216483217115E-06 0.0104800581470382" rpy="0 0 0" />
      <mass value="0.00654982478226948" />
      <inertia ixx="4.43422823045881E-07" ixy="-2.65801609336249E-12" ixz="2.72879331079687E-08" iyy="4.58697754707372E-07" iyz="-8.52654749041276E-11" izz="1.746844667607E-07" />
    </inertial>
    <visual>
      <origin xyz="0 0 0" rpy="0 0 0" />
      <geometry>
        <mesh filename="../linkerhand-urdf/l10/right/meshes/middle_proximal.STL" />
      </geometry>
      <material name="right_l10_silver_white">
        <color rgba="0.86 0.88 0.88 1" />
      </material>
    </visual>
    <collision>
      <origin xyz="0 0 0" rpy="0 0 0" />
      <geometry>
        <mesh filename="../linkerhand-urdf/l10/right/meshes/middle_proximal.STL" />
      </geometry>
    </collision>
  </link>
  <joint name="right_l10_middle_mcp_pitch" type="revolute">
    <origin xyz="-0.0021316 0.0076542 0.15281" rpy="0 0 0" />
    <parent link="right_l10_hand_base_link" />
    <child link="right_l10_middle_proximal" />
    <axis xyz="0 1 0" />
    <limit lower="0" upper="1.3607" effort="100" velocity="1" />
  </joint>
  <link name="right_l10_middle_middle">
    <inertial>
      <origin xyz="-0.00261699473119732 -2.09526685195343E-06 0.0110132928110042" rpy="0 0 0" />
      <mass value="0.00283043635504843" />
      <inertia ixx="2.60196021834948E-07" ixy="5.79547865424082E-11" ixz="4.1391958359388E-08" iyy="2.33077669434872E-07" iyz="-2.91048412607941E-11" izz="1.27384845266404E-07" />
    </inertial>
    <visual>
      <origin xyz="0 0 0" rpy="0 0 0" />
      <geometry>
        <mesh filename="../linkerhand-urdf/l10/right/meshes/middle_middle.STL" />
      </geometry>
      <material name="right_l10_silver_white">
        <color rgba="0.86 0.88 0.88 1" />
      </material>
    </visual>
    <collision>
      <origin xyz="0 0 0" rpy="0 0 0" />
      <geometry>
        <mesh filename="../linkerhand-urdf/l10/right/meshes/middle_middle.STL" />
      </geometry>
    </collision>
  </link>
  <joint name="right_l10_middle_pip" type="revolute">
    <origin xyz="-0.001397 0 0.035623" rpy="0 0 0" />
    <parent link="right_l10_middle_proximal" />
    <child link="right_l10_middle_middle" />
    <axis xyz="0 1 0" />
    <limit lower="0" upper="1.8317" effort="100" velocity="1" />
    <mimic joint="right_l10_middle_mcp_pitch" multiplier="1.3462" offset="0" />
  </joint>
  <link name="right_l10_middle_distal">
    <inertial>
      <origin xyz="-0.000728492686368068 5.23463091207845E-06 0.0121446078355904" rpy="0 0 0" />
      <mass value="0.0031445865911477" />
      <inertia ixx="1.6319430020531E-07" ixy="1.99064061423831E-11" ixz="4.34469141575623E-08" iyy="1.48366133401933E-07" iyz="-2.0274172110168E-10" izz="9.86853634492536E-08" />
    </inertial>
    <visual>
      <origin xyz="0 0 0" rpy="0 0 0" />
      <geometry>
        <mesh filename="../linkerhand-urdf/l10/right/meshes/middle_distal.STL" />
      </geometry>
      <material name="right_l10_silver_white">
        <color rgba="0.86 0.88 0.88 1" />
      </material>
    </visual>
    <collision>
      <origin xyz="0 0 0" rpy="0 0 0" />
      <geometry>
        <mesh filename="../linkerhand-urdf/l10/right/meshes/middle_distal.STL" />
      </geometry>
    </collision>
  </link>
  <joint name="right_l10_middle_dip" type="revolute">
    <origin xyz="-0.0055098 0 0.025656" rpy="0 0 0" />
    <parent link="right_l10_middle_middle" />
    <child link="right_l10_middle_distal" />
    <axis xyz="0 1 0" />
    <limit lower="0" upper="0.628" effort="100" velocity="1" />
    <mimic joint="right_l10_middle_mcp_pitch" multiplier="0.4616" offset="0" />
  </joint>
  <link name="right_l10_ring_metacarpals">
    <inertial>
      <origin xyz="-0.000473392019250147 -6.96702861586324E-07 0.00909067743061451" rpy="0 0 0" />
      <mass value="0.00903700347459463" />
      <inertia ixx="4.90035722472612E-07" ixy="3.89143802227228E-11" ixz="-2.78580197566549E-08" iyy="7.37380420538669E-07" iyz="6.37050140810733E-11" izz="5.52381285093452E-07" />
    </inertial>
    <visual>
      <origin xyz="0 0 0" rpy="0 0 0" />
      <geometry>
        <mesh filename="../linkerhand-urdf/l10/right/meshes/ring_metacarpals.STL" />
      </geometry>
      <material name="right_l10_silver_white">
        <color rgba="0.86 0.88 0.88 1" />
      </material>
    </visual>
    <collision>
      <origin xyz="0 0 0" rpy="0 0 0" />
      <geometry>
        <mesh filename="../linkerhand-urdf/l10/right/meshes/ring_metacarpals.STL" />
      </geometry>
    </collision>
  </link>
  <joint name="right_l10_ring_mcp_roll" type="revolute">
    <origin xyz="-0.0021643 -0.011346 0.13253" rpy="0 0 0" />
    <parent link="right_l10_hand_base_link" />
    <child link="right_l10_ring_metacarpals" />
    <axis xyz="0.99996 0 0.0087265" />
    <limit lower="0" upper="0.2181" effort="100" velocity="1" />
  </joint>
  <link name="right_l10_ring_proximal">
    <inertial>
      <origin xyz="-0.000221412177759527 1.17116513872681E-06 0.0104801549347171" rpy="0 0 0" />
      <mass value="0.00654982867950541" />
      <inertia ixx="4.43447863010516E-07" ixy="-2.73227024213763E-12" ixz="2.71645164102371E-08" iyy="4.58697895506594E-07" iyz="-8.52846225435011E-11" izz="1.74659590566364E-07" />
    </inertial>
    <visual>
      <origin xyz="0 0 0" rpy="0 0 0" />
      <geometry>
        <mesh filename="../linkerhand-urdf/l10/right/meshes/ring_proximal.STL" />
      </geometry>
      <material name="right_l10_silver_white">
        <color rgba="0.86 0.88 0.88 1" />
      </material>
    </visual>
    <collision>
      <origin xyz="0 0 0" rpy="0 0 0" />
      <geometry>
        <mesh filename="../linkerhand-urdf/l10/right/meshes/ring_proximal.STL" />
      </geometry>
    </collision>
  </link>
  <joint name="right_l10_ring_mcp_pitch" type="revolute">
    <origin xyz="0.0020763 0 0.015294" rpy="0 0 0" />
    <parent link="right_l10_ring_metacarpals" />
    <child link="right_l10_ring_proximal" />
    <axis xyz="0 1 0" />
    <limit lower="0" upper="1.3607" effort="100" velocity="1" />
  </joint>
  <link name="right_l10_ring_middle">
    <inertial>
      <origin xyz="-0.00259932539169275 -2.09536925854445E-06 0.0110174765352322" rpy="0 0 0" />
      <mass value="0.00283043628669241" />
      <inertia ixx="2.6032847037415E-07" ixy="5.79104972037516E-11" ixz="4.11787063652271E-08" iyy="2.33077663802866E-07" iyz="-2.91978956610415E-11" izz="1.27252388488073E-07" />
    </inertial>
    <visual>
      <origin xyz="0 0 0" rpy="0 0 0" />
      <geometry>
        <mesh filename="../linkerhand-urdf/l10/right/meshes/ring_middle.STL" />
      </geometry>
      <material name="right_l10_silver_white">
        <color rgba="0.86 0.88 0.88 1" />
      </material>
    </visual>
    <collision>
      <origin xyz="0 0 0" rpy="0 0 0" />
      <geometry>
        <mesh filename="../linkerhand-urdf/l10/right/meshes/ring_middle.STL" />
      </geometry>
    </collision>
  </link>
  <joint name="right_l10_ring_pip" type="revolute">
    <origin xyz="-0.0013807 0 0.035624" rpy="0 0 0" />
    <parent link="right_l10_ring_proximal" />
    <child link="right_l10_ring_middle" />
    <axis xyz="0 1 0" />
    <limit lower="0" upper="1.8317" effort="100" velocity="1" />
    <mimic joint="right_l10_ring_mcp_pitch" multiplier="1.3462" offset="0" />
  </joint>
  <link name="right_l10_ring_distal">
    <inertial>
      <origin xyz="-0.000710605070655887 5.23486441320054E-06 0.0121456664241844" rpy="0 0 0" />
      <mass value="0.0031445863941225" />
      <inertia ixx="1.6332208655443E-07" ixy="1.96096284326007E-11" ixz="4.33517042915493E-08" iyy="1.48366090032445E-07" iyz="-2.02778843611257E-10" izz="9.85575241184011E-08" />
    </inertial>
    <visual>
      <origin xyz="0 0 0" rpy="0 0 0" />
      <geometry>
        <mesh filename="../linkerhand-urdf/l10/right/meshes/ring_distal.STL" />
      </geometry>
      <material name="right_l10_silver_white">
        <color rgba="0.86 0.88 0.88 1" />
      </material>
    </visual>
    <collision>
      <origin xyz="0 0 0" rpy="0 0 0" />
      <geometry>
        <mesh filename="../linkerhand-urdf/l10/right/meshes/ring_distal.STL" />
      </geometry>
    </collision>
  </link>
  <joint name="right_l10_ring_dip" type="revolute">
    <origin xyz="-0.0054686 0 0.025665" rpy="0 0 0" />
    <parent link="right_l10_ring_middle" />
    <child link="right_l10_ring_distal" />
    <axis xyz="0 1 0" />
    <limit lower="0" upper="0.628" effort="100" velocity="1" />
    <mimic joint="right_l10_ring_mcp_pitch" multiplier="0.4616" offset="0" />
  </joint>
  <link name="right_l10_pinky_metacarpals">
    <inertial>
      <origin xyz="-0.000473392019250103 -6.96702861589793E-07 0.00909067743061448" rpy="0 0 0" />
      <mass value="0.00903700347459465" />
      <inertia ixx="4.90035722472611E-07" ixy="3.89143802264643E-11" ixz="-2.78580197566552E-08" iyy="7.37380420538668E-07" iyz="6.37050140815369E-11" izz="5.52381285093452E-07" />
    </inertial>
    <visual>
      <origin xyz="0 0 0" rpy="0 0 0" />
      <geometry>
        <mesh filename="../linkerhand-urdf/l10/right/meshes/pinky_metacarpals.STL" />
      </geometry>
      <material name="right_l10_silver_white">
        <color rgba="0.86 0.88 0.88 1" />
      </material>
    </visual>
    <collision>
      <origin xyz="0 0 0" rpy="0 0 0" />
      <geometry>
        <mesh filename="../linkerhand-urdf/l10/right/meshes/pinky_metacarpals.STL" />
      </geometry>
    </collision>
  </link>
  <joint name="right_l10_pinky_mcp_roll" type="revolute">
    <origin xyz="-0.00012074 -0.030346 0.12755" rpy="0 0 0" />
    <parent link="right_l10_hand_base_link" />
    <child link="right_l10_pinky_metacarpals" />
    <axis xyz="0.99996 0 0.0087265" />
    <limit lower="0" upper="0.3489" effort="100" velocity="1" />
  </joint>
  <link name="right_l10_pinky_proximal">
    <inertial>
      <origin xyz="-0.000221412258607754 1.17103683876935E-06 0.0104801532987067" rpy="0 0 0" />
      <mass value="0.00654982918810593" />
      <inertia ixx="4.43447910769094E-07" ixy="-2.73411126621624E-12" ixz="2.71644852567342E-08" iyy="4.58697939807031E-07" iyz="-8.52970212446317E-11" izz="1.74659590066949E-07" />
    </inertial>
    <visual>
      <origin xyz="0 0 0" rpy="0 0 0" />
      <geometry>
        <mesh filename="../linkerhand-urdf/l10/right/meshes/pinky_proximal.STL" />
      </geometry>
      <material name="right_l10_silver_white">
        <color rgba="0.86 0.88 0.88 1" />
      </material>
    </visual>
    <collision>
      <origin xyz="0 0 0" rpy="0 0 0" />
      <geometry>
        <mesh filename="../linkerhand-urdf/l10/right/meshes/pinky_proximal.STL" />
      </geometry>
    </collision>
  </link>
  <joint name="right_l10_pinky_mcp_pitch" type="revolute">
    <origin xyz="0.0020763 0 0.015294" rpy="0 0 0" />
    <parent link="right_l10_pinky_metacarpals" />
    <child link="right_l10_pinky_proximal" />
    <axis xyz="0 1 0" />
    <limit lower="0" upper="1.3607" effort="100" velocity="1" />
  </joint>
  <link name="right_l10_pinky_middle">
    <inertial>
      <origin xyz="-0.002599325191487 -2.09526073984695E-06 0.0110174765184069" rpy="0 0 0" />
      <mass value="0.00283043635595589" />
      <inertia ixx="2.60328472325978E-07" ixy="5.7907596343404E-11" ixz="4.11787064048009E-08" iyy="2.33077669786026E-07" iyz="-2.91977981214484E-11" izz="1.27252395425297E-07" />
    </inertial>
    <visual>
      <origin xyz="0 0 0" rpy="0 0 0" />
      <geometry>
        <mesh filename="../linkerhand-urdf/l10/right/meshes/pinky_middle.STL" />
      </geometry>
      <material name="right_l10_silver_white">
        <color rgba="0.86 0.88 0.88 1" />
      </material>
    </visual>
    <collision>
      <origin xyz="0 0 0" rpy="0 0 0" />
      <geometry>
        <mesh filename="../linkerhand-urdf/l10/right/meshes/pinky_middle.STL" />
      </geometry>
    </collision>
  </link>
  <joint name="right_l10_pinky_pip" type="revolute">
    <origin xyz="-0.0013807 0 0.035624" rpy="0 0 0" />
    <parent link="right_l10_pinky_proximal" />
    <child link="right_l10_pinky_middle" />
    <axis xyz="0 1 0" />
    <limit lower="0" upper="1.8317" effort="100" velocity="1" />
    <mimic joint="right_l10_pinky_mcp_pitch" multiplier="1.3462" offset="0" />
  </joint>
  <link name="right_l10_pinky_distal">
    <inertial>
      <origin xyz="-0.000710605211329151 5.23471293070038E-06 0.0121456666744262" rpy="0 0 0" />
      <mass value="0.0031445864920905" />
      <inertia ixx="1.63322099233008E-07" ixy="1.96074242691561E-11" ixz="4.33517077122639E-08" iyy="1.48366101127732E-07" iyz="-2.02773897050006E-10" izz="9.85575276143507E-08" />
    </inertial>
    <visual>
      <origin xyz="0 0 0" rpy="0 0 0" />
      <geometry>
        <mesh filename="../linkerhand-urdf/l10/right/meshes/pinky_distal.STL" />
      </geometry>
      <material name="right_l10_silver_white">
        <color rgba="0.86 0.88 0.88 1" />
      </material>
    </visual>
    <collision>
      <origin xyz="0 0 0" rpy="0 0 0" />
      <geometry>
        <mesh filename="../linkerhand-urdf/l10/right/meshes/pinky_distal.STL" />
      </geometry>
    </collision>
  </link>
  <joint name="right_l10_pinky_dip" type="revolute">
    <origin xyz="-0.0054686 0 0.025665" rpy="0 0 0" />
    <parent link="right_l10_pinky_middle" />
    <child link="right_l10_pinky_distal" />
    <axis xyz="0 1 0" />
    <limit lower="0" upper="0.628" effort="100" velocity="1" />
    <mimic joint="right_l10_pinky_mcp_pitch" multiplier="0.4616" offset="0" />
  </joint>
  <joint name="right_revo2_flange_to_l10_hand" type="fixed">
    <origin xyz="0 0 0" rpy="0 -0 1.57079633" />
    <parent link="right_revo2_flange" />
    <child link="right_l10_hand_base_link" />
  </joint>
  <link name="d455_body">
    <inertial>
      <origin xyz="0 0 0" rpy="0 0 0" />
      <mass value="0.116" />
      <inertia ixx="0.000156764333" ixy="0" ixz="0" iyy="1.46643333e-05" iyz="0" izz="0.000155169333" />
    </inertial>
    <visual>
      <origin xyz="0 0 0" rpy="0 0 0" />
      <geometry>
        <box size="0.026 0.124 0.029" />
      </geometry>
      <material name="d455_body_material">
        <color rgba="0.08 0.08 0.08 1" />
      </material>
    </visual>
  </link>
  <joint name="combined_root_to_d455_body" type="fixed">
    <origin xyz="-0.075778 0.001444 1.285333" rpy="-1.2246468e-16 0.698131701 3.14159265" />
    <parent link="combined_root" />
    <child link="d455_body" />
  </joint>
</robot>